<?xml version='1.0'?>

<robot name="udacity_bot" xmlns:xacro="http://www.ros.org/wiki/xacro">
  <xacro:include filename="$(find slam_project)/urdf/udacity_bot.gazebo" />


  <link name="robot_footprint"></link>

  <joint name="robot_footprint_joint" type="fixed">
    <origin xyz="0 0 0" rpy="0 0 0" />
    <parent link="robot_footprint"/>
    <child link="chassis" />
  </joint>

  <link name='chassis'>
    <pose>0 0 0.1 0 0 0</pose>

    <inertial> 
      <mass value="10.0"/> <!-- CUSTOM ROBOT -->
      <origin xyz="0.0 0 0" rpy=" 0 0 0"/>
      <inertia
          ixx="0.1" ixy="0" ixz="0"
          iyy="0.1" iyz="0"
          izz="0.1"
      />
    </inertial>

    <collision name='chassis_collision'>
      <origin xyz="0 0 0" rpy=" 0 0 0"/> 
      <geometry>
        <cylinder radius='0.1' length='0.01'/> <!-- CUSTOM ROBOT -->
      </geometry>
    </collision>

    <visual name='chassis_visual'>
      <origin xyz="0 0 0" rpy=" 0 0 0"/>
      <geometry>
        <cylinder radius='0.1' length='0.01'/>  <!-- CUSTOM ROBOT -->
      </geometry>
      <material name="green">
         <color rgba="0.2 0.1 1 0.8"/>  <!-- CUSTOM ROBOT -->
      </material>
    </visual>


    <collision name='back_caster_collision'>
      <origin xyz="-0.10 0 -0.025" rpy=" 0 0 0"/>
      <geometry>
        <sphere radius="0.0249"/> <!-- CUSTOM ROBOT -->
      </geometry>
    </collision>

    <visual name='back_caster_visual'>
      <origin xyz="-0.10 0 -0.025" rpy=" 0 0 0"/>
      <geometry>
        <sphere radius="0.025"/> <!-- CUSTOM ROBOT -->
      </geometry>
    </visual>

    <collision name='front_caster_collision'>
      <origin xyz="0.10 0 -0.025" rpy=" 0 0 0"/>
      <geometry>
        <sphere radius="0.0249"/> <!-- CUSTOM ROBOT -->
      </geometry>
    </collision>

    <visual name='front_caster_visual'>
      <origin xyz="0.10 0 -0.025" rpy=" 0 0 0"/>
      <geometry>
        <sphere radius="0.025"/> <!-- CUSTOM ROBOT -->
      </geometry>
    </visual>

  </link>

  <link name='left_wheel'>

    <inertial>
      <mass value="1.0"/> <!-- CUSTOM ROBOT -->
      <origin xyz="0.0 0 0" rpy=" 0 1.5707 1.5707"/>
      <inertia
          ixx="0.1" ixy="0" ixz="0"
          iyy="0.1" iyz="0"
          izz="0.1"
      />
    </inertial>

    <collision name='left_wheel_collision'>
      <origin xyz="0.0 0 0" rpy=" 0 1.5707 1.5707"/>
      <geometry>
        <cylinder radius='0.05' length='0.025'/> <!-- CUSTOM ROBOT -->
      </geometry>
    </collision>

    <visual name='left_wheel_visual'>
      <origin xyz="0.0 0 0" rpy=" 0 1.5707 1.5707"/>
      <geometry>
        <cylinder radius='0.05' length='0.025'/> <!-- CUSTOM ROBOT -->
      </geometry>
      <material name="gray">
         <color rgba="0.2 0.2 0.2 0.8"/>
      </material>
    </visual>

  </link>

  <link name='right_wheel'>

    <inertial>
      <mass value="1.0"/> <!-- CUSTOM ROBOT -->
      <origin xyz="0.0 0 0" rpy=" 0 1.5707 1.5707"/>
      <inertia
          ixx="0.1" ixy="0" ixz="0"
          iyy="0.1" iyz="0"
          izz="0.1"
      />
    </inertial>

    <collision name='right_weel_collision'>
      <origin xyz="0.0 0 0" rpy=" 0 1.5707 1.5707"/>
      <geometry>
        <cylinder radius='0.05' length='0.025'/> <!-- CUSTOM ROBOT -->
      </geometry>
    </collision>

    <visual name='right_wheel_visual'>
      <origin xyz="0.0 0 0" rpy=" 0 1.5707 1.5707"/>
      <geometry>
        <cylinder radius='0.05' length='0.025'/> <!-- CUSTOM ROBOT -->
      </geometry>
      <material name="gray">
         <color rgba="0.2 0.2 0.2 0.8"/>
      </material>
    </visual>

  </link>


  <link name='camera_link'>

    <inertial>
      <mass value="0.1"/>
      <origin xyz="0.0 0 0" rpy=" 0 0 0"/>
      <inertia
          ixx="1e-6" ixy="0" ixz="0"
          iyy="1e-6" iyz="0"
          izz="1e-6"
      />
    </inertial>

    <collision name='camera_collision'>
      <origin xyz="0.0 0 0" rpy=" 0 0 0"/>
      <geometry>
        <box size="0.05 0.05 0.05"/>
      </geometry>
    </collision>

    <visual name='camera_visual'>
      <origin xyz="0.0 0 0" rpy=" 0 0 0"/>
      <geometry>
        <box size="0.05 0.05 0.05"/>
      </geometry>
    </visual>

  </link>

<link name="camera_rgbd_frame">

    <inertial>
      <mass value="0.1"/>
      <origin xyz="0 0 0" rpy=" 0 0 0"/>
      <inertia
          ixx="1e-6" ixy="0" ixz="0"
          iyy="1e-6" iyz="0"
          izz="1e-6"
      />
    </inertial>

    <collision name="camera_rgbd_frame_collision">
      <origin xyz="0 0 0" rpy="0 0 0"/>
       <geometry>
        <box size="0.05 0.05 0.05"/>
      </geometry>
    </collision>

     <visual name="camera_rgbd_frame_visual">
      <origin xyz="0 0 0" rpy="0 0 0"/>
       <geometry>
        <box size="0.05 0.05 0.05"/>
      </geometry>
    </visual>


</link>
 
  <link name='hokuyo'>

    <inertial>
      <mass value="0.1"/>
      <origin xyz="0.0 0 0" rpy=" 0 0 0"/>
      <inertia
          ixx="1e-6" ixy="0" ixz="0"
          iyy="1e-6" iyz="0"
          izz="1e-6"
      />
    </inertial>

    <collision name='hokuyo_collision'>
      <origin xyz="0.0 0 0" rpy=" 0 0 0"/>
      <geometry>
        <box size="0.1 0.1 0.1"/>
      </geometry>
    </collision>

    <visual name='hokuyo_visual'>
      <origin xyz="0.0 0 0" rpy=" 0 0 0"/>
      <geometry>
        <mesh filename="package://slam_project/meshes/hokuyo.dae"/>
      </geometry>
    </visual>

  </link>

  <joint type="continuous" name="left_wheel_hinge">
    <origin xyz="0 0.125 0" rpy="0 0 0"/><!-- CUSTOM ROBOT -->
    <child link="left_wheel"/>
    <parent link="chassis"/>
    <axis xyz="0 1 0" rpy="0 0 0"/>
    <limit effort="10000" velocity="1000"/>
    <joint_properties damping="1.0" friction="1.0"/>
  </joint>

  <joint type="continuous" name="right_wheel_hinge">
    <origin xyz="0 -0.125 0" rpy="0 0 0"/><!-- CUSTOM ROBOT -->
    <child link="right_wheel"/>
    <parent link="chassis"/>
    <axis xyz="0 1 0" rpy="0 0 0"/>
    <limit effort="10000" velocity="1000"/>
    <joint_properties damping="1.0" friction="1.0"/>
  </joint>

  <joint type="fixed" name="camera_joint">
    <origin xyz="0.1 0 0.03" rpy="0 0 0"/><!-- CUSTOM ROBOT -->
    <child link="camera_link"/>
    <parent link="chassis"/>
    <axis xyz="0 1 0" rpy="0 0 0"/>
    <limit effort="10000" velocity="1000"/>
    <joint_properties damping="1.0" friction="1.0"/>
  </joint>

  <joint type="fixed" name="hokuyo_joint">
    <origin xyz="0.1 0 0.1" rpy="0 0 0"/><!-- CUSTOM ROBOT -->
    <child link="hokuyo"/>
    <parent link="chassis"/>
    <axis xyz="0 1 0" rpy="0 0 0"/>
    <limit effort="10000" velocity="1000"/>
    <joint_properties damping="1.0" friction="1.0"/>
  </joint>
 <joint name="rgbd_joint" type="fixed">
    <origin xyz="0.1 0 0.1" rpy="-1.5707 0  -1.5707" />
    <parent link="chassis"/>
    <child link="camera_rgbd_frame"/>
  </joint>

</robot>

